Workbook

Sheet Pharmacy_Receipts
A1: DR_Date | B1: DR_Time | C1: DR_CheckNo | D1: DR_DocNo | E1: DR_Department | F1: DR_KKM | G1: DR_DocType | H1: DR_PaymentType | I1: DR_DrugCode | J1: DR_DrugName | K1: DR_Supplier | L1: DR_Producer | M1: DR_Qty | N1: DR_PurchasePrice | O1: DR_RetailPrice | P1: DR_SaleDiscount | Q1: DR_CardDiscount | R1: DR_BonusCard | S1: DR_EmployeeTab | T1: DR_SaleType | U1: DR_Position | V1: Amount | W1: BillNo
A2: 44788 | B2: 0.36225694 | C2: 1000 | D2: 13002561 | E2: 13 | F2: 22589 | G2: Retail Sale | H2: 15 | I2: 62322 | J2: Drug Item 86 Ointment | K2: Pulse | L2: Bayer | M2: 3 | N2: 219.73 | O2: 367.66 | P2: 0 | Q2: 0 | S2: 29 | T2: 1 | U2: 4 | V2: 367.66 | W2: 13130000000
A3: 44778 | B3: 0.70761574 | C3: 1001 | D3: 13002561 | E3: 13 | F3: 22589 | G3: Retail Sale | H3: 18 | I3: 78979 | J3: Drug Item 54 Tablets | K3: Avesta | L3: Dr. Reddy's | M3: 2 | N3: 47.12 | O3: 62.37 | P3: 6.24 | Q3: 6.24 | R3: BONUS_CARD | S3: 29 | T3: 1 | U3: 5 | V3: 56.13 | W3: 13130000001
A4: 44800 | B4: 0.74162037 | C4: 1002 | D4: 13002561 | E4: 13 | F4: 22589 | G4: Retail Sale | H4: 18 | I4: 15418 | J4: Drug Item 17 Drops | K4: Avesta | L4: Novartis | M4: 3 | N4: 426.75 | O4: 695.12 | P4: 0 | Q4: 0 | S4: 29 | T4: 1 | U4: 6 | V4: 695.12 | W4: 13130000002
A5: 44801 | B5: 0.47509259 | C5: 1003 | D5: 13002561 | E5: 13 | F5: 22589 | G5: Retail Sale | H5: 18 | I5: 51597 | J5: Drug Item 48 Injection | K5: Pulse | L5: Sanofi | M5: 1 | N5: 522.31 | O5: 675.15 | P5: 33.76 | Q5: 33.76 | R5: BONUS_CARD | S5: 29 | T5: 1 | U5: 1 | V5: 641.39 | W5: 13130000003
A6: 44787 | B6: 0.43666667 | C6: 1004 | D6: 13002561 | E6: 13 | F6: 22589 | G6: Retail Sale | H6: 15 | I6: 36786 | J6: Drug Item 5 Ointment | K6: Pulse | L6: Takeda | M6: 1 | N6: 48.97 | O6: 81.78 | P6: 4.09 | Q6: 4.09 | R6: BONUS_CARD | S6: 29 | T6: 1 | U6: 1 | V6: 77.69 | W6: 13130000004
A7: 44801 | B7: 0.66813657 | C7: 1005 | D7: 13002561 | E7: 13 | F7: 22589 | G7: Retail Sale | H7: 18 | I7: 83535 | J7: Drug Item 76 Cream | K7: Grand Capital | L7: TEVA | M7: 3 | N7: 162.72 | O7: 219.99 | P7: 0 | Q7: 0 | S7: 29 | T7: 1 | U7: 3 | V7: 219.99 | W7: 13130000005
A8: 44797 | B8: 0.6374537 | C8: 1006 | D8: 13002561 | E8: 13 | F8: 22589 | G8: Retail Sale | H8: 18 | I8: 17154 | J8: Drug Item 14 Ointment | K8: Grand Capital | L8: Novartis | M8: 3 | N8: 456.34 | O8: 766.02 | P8: 38.3 | Q8: 38.3 | R8: BONUS_CARD | S8: 29 | T8: 1 | U8: 4 | V8: 727.72 | W8: 13130000006
A9: 44797 | B9: 0.75806713 | C9: 1007 | D9: 13002561 | E9: 13 | F9: 22589 | G9: Retail Sale | H9: 18 | I9: 62677 | J9: Drug Item 80 Drops | K9: Pulse | L9: Sanofi | M9: 3 | N9: 455.3 | O9: 625.23 | P9: 31.26 | Q9: 31.26 | R9: BONUS_CARD | S9: 29 | T9: 1 | U9: 4 | V9: 593.97 | W9: 13130000007
A10: 44778 | B10: 0.41453704 | C10: 1008 | D10: 13002561 | E10: 13 | F10: 22589 | G10: Retail Sale | H10: 15 | I10: 24428 | J10: Drug Item 76 Cream | K10: Grand Capital | L10: Dr. Reddy's | M10: 2 | N10: 359.78 | O10: 481.52 | P10: 0 | Q10: 0 | S10: 29 | T10: 1 | U10: 3 | V10: 481.52 | W10: 13130000008
A11: 44798 | B11: 0.68673611 | C11: 1009 | D11: 13002561 | E11: 13 | F11: 22589 | G11: Retail Sale | H11: 18 | I11: 69547 | J11: Drug Item 31 Cream | K11: Grand Capital | L11: TEVA | M11: 1 | N11: 110 | O11: 141.38 | P11: 7.07 | Q11: 7.07 | R11: BONUS_CARD | S11: 29 | T11: 1 | U11: 3 | V11: 134.31 | W11: 13130000009
A12: 44781 | B12: 0.34626157 | C12: 1010 | D12: 13002561 | E12: 13 | F12: 22589 | G12: Retail Sale | H12: 15 | I12: 83441 | J12: Drug Item 89 Drops | K12: Katren | L12: Takeda | M12: 2 | N12: 579.29 | O12: 843.98 | P12: 84.4 | Q12: 84.4 | R12: BONUS_CARD | S12: 29 | T12: 1 | U12: 6 | V12: 759.58 | W12: 13130000010
A13: 44803 | B13: 0.88873843 | C13: 1011 | D13: 13002561 | E13: 13 | F13: 22589 | G13: Retail Sale | H13: 15 | I13: 62573 | J13: Drug Item 86 Ointment | K13: Protek | L13: Novartis | M13: 3 | N13: 155.22 | O13: 199.26 | P13: 19.93 | Q13: 19.93 | R13: BONUS_CARD | S13: 29 | T13: 1 | U13: 1 | V13: 179.33 | W13: 13130000011
A14: 44774 | B14: 0.90581019 | C14: 1012 | D14: 13002561 | E14: 13 | F14: 22589 | G14: Retail Sale | H14: 15 | I14: 12185 | J14: Drug Item 62 Drops | K14: Protek | L14: KRKA | M14: 1 | N14: 345.11 | O14: 519.76 | P14: 25.99 | Q14: 25.99 | R14: BONUS_CARD | S14: 29 | T14: 1 | U14: 3 | V14: 493.77 | W14: 13130000012
A15: 44780 | B15: 0.56715278 | C15: 1013 | D15: 13002561 | E15: 13 | F15: 22589 | G15: Retail Sale | H15: 18 | I15: 99935 | J15: Drug Item 45 Tablets | K15: Protek | L15: Dr. Reddy's | M15: 1 | N15: 457.19 | O15: 746.15 | P15: 0 | Q15: 0 | S15: 29 | T15: 1 | U15: 3 | V15: 746.15 | W15: 13130000013
A16: 44799 | B16: 0.61986111 | C16: 1014 | D16: 13002561 | E16: 13 | F16: 22589 | G16: Retail Sale | H16: 15 | I16: 64118 | J16: Drug Item 1 Capsules | K16: Avesta | L16: Novartis | M16: 3 | N16: 61.15 | O16: 103.4 | P16: 10.34 | Q16: 10.34 | R16: BONUS_CARD | S16: 29 | T16: 1 | U16: 3 | V16: 93.06 | W16: 13130000014
A17: 44780 | B17: 0.44603009 | C17: 1015 | D17: 13002561 | E17: 13 | F17: 22589 | G17: Retail Sale | H17: 15 | I17: 12583 | J17: Drug Item 4 Cream | K17: Pulse | L17: Pfizer | M17: 2 | N17: 210.41 | O17: 334.92 | P17: 0 | Q17: 0 | S17: 29 | T17: 1 | U17: 2 | V17: 334.92 | W17: 13130000015
A18: 44788 | B18: 0.69896991 | C18: 1016 | D18: 13002561 | E18: 13 | F18: 22589 | G18: Retail Sale | H18: 15 | I18: 74327 | J18: Drug Item 39 Injection | K18: Pulse | L18: Pfizer | M18: 2 | N18: 557.52 | O18: 744.91 | P18: 0 | Q18: 0 | S18: 29 | T18: 1 | U18: 5 | V18: 744.91 | W18: 13130000016
A19: 44783 | B19: 0.49201389 | C19: 1017 | D19: 13002561 | E19: 13 | F19: 22589 | G19: Retail Sale | H19: 18 | I19: 45437 | J19: Drug Item 26 Drops | K19: Grand Capital | L19: Takeda | M19: 3 | N19: 195.09 | O19: 312.2 | P19: 15.61 | Q19: 15.61 | R19: BONUS_CARD | S19: 29 | T19: 1 | U19: 3 | V19: 296.59 | W19: 13130000017
A20: 44789 | B20: 0.88840278 | C20: 1018 | D20: 13002561 | E20: 13 | F20: 22589 | G20: Retail Sale | H20: 18 | I20: 37457 | J20: Drug Item 49 Cream | K20: Katren | L20: Bayer | M20: 1 | N20: 178.09 | O20: 286.41 | P20: 28.64 | Q20: 28.64 | R20: BONUS_CARD | S20: 29 | T20: 1 | U20: 6 | V20: 257.77 | W20: 13130000018
A21: 44787 | B21: 0.8121412 | C21: 1019 | D21: 13002561 | E21: 13 | F21: 22589 | G21: Retail Sale | H21: 18 | I21: 92747 | J21: Drug Item 20 Syrup | K21: Katren | L21: Novartis | M21: 2 | N21: 400.67 | O21: 551 | P21: 55.1 | Q21: 55.1 | R21: BONUS_CARD | S21: 29 | T21: 1 | U21: 3 | V21: 495.9 | W21: 13130000019
A22: 44804 | B22: 0.58414352 | C22: 1020 | D22: 13002561 | E22: 13 | F22: 22589 | G22: Retail Sale | H22: 18 | I22: 17699 | J22: Drug Item 50 Ointment | K22: Katren | L22: TEVA | M22: 3 | N22: 78.69 | O22: 116.24 | P22: 11.62 | Q22: 11.62 | R22: BONUS_CARD | S22: 29 | T22: 1 | U22: 4 | V22: 104.62 | W22: 13130000020
A23: 44776 | B23: 0.39581019 | C23: 1021 | D23: 13002561 | E23: 13 | F23: 22589 | G23: Retail Sale | H23: 15 | I23: 22329 | J23: Drug Item 36 Tablets | K23: Katren | L23: Novartis | M23: 2 | N23: 598.53 | O23: 839.18 | P23: 41.96 | Q23: 41.96 | R23: BONUS_CARD | S23: 29 | T23: 1 | U23: 6 | V23: 797.22 | W23: 13130000021
A24: 44774 | B24: 0.87270833 | C24: 1022 | D24: 13002561 | E24: 13 | F24: 22589 | G24: Retail Sale | H24: 15 | I24: 72796 | J24: Drug Item 53 Drops | K24: Protek | L24: Novartis | M24: 3 | N24: 551.38 | O24: 733.39 | P24: 36.67 | Q24: 36.67 | R24: BONUS_CARD | S24: 29 | T24: 1 | U24: 2 | V24: 696.72 | W24: 13130000022
A25: 44804 | B25: 0.51577546 | C25: 1023 | D25: 13002561 | E25: 13 | F25: 22589 | G25: Retail Sale | H25: 15 | I25: 58541 | J25: Drug Item 3 Injection | K25: Pharmcomplect | L25: Novartis | M25: 1 | N25: 431.25 | O25: 649.36 | P25: 32.47 | Q25: 32.47 | R25: BONUS_CARD | S25: 29 | T25: 1 | U25: 6 | V25: 616.89 | W25: 13130000023
A26: 44796 | B26: 0.50699074 | C26: 1024 | D26: 13002561 | E26: 13 | F26: 22589 | G26: Retail Sale | H26: 15 | I26: 58374 | J26: Drug Item 85 Cream | K26: Pulse | L26: Pfizer | M26: 3 | N26: 279.78 | O26: 409.16 | P26: 0 | Q26: 0 | S26: 29 | T26: 1 | U26: 3 | V26: 409.16 | W26: 13130000024
A27: 44799 | B27: 0.41412037 | C27: 1025 | D27: 13002561 | E27: 13 | F27: 22589 | G27: Retail Sale | H27: 15 | I27: 83109 | J27: Drug Item 80 Drops | K27: Grand Capital | L27: Sanofi | M27: 2 | N27: 422.8 | O27: 547.39 | P27: 27.37 | Q27: 27.37 | R27: BONUS_CARD | S27: 29 | T27: 1 | U27: 5 | V27: 520.02 | W27: 13130000025
A28: 44784 | B28: 0.78320602 | C28: 1026 | D28: 13002561 | E28: 13 | F28: 22589 | G28: Retail Sale | H28: 18 | I28: 29788 | J28: Drug Item 16 Spray | K28: Avesta | L28: TEVA | M28: 1 | N28: 471.03 | O28: 747.49 | P28: 37.37 | Q28: 37.37 | R28: BONUS_CARD | S28: 29 | T28: 1 | U28: 5 | V28: 710.12 | W28: 13130000026
A29: 44775 | B29: 0.65376157 | C29: 1027 | D29: 13002561 | E29: 13 | F29: 22589 | G29: Retail Sale | H29: 18 | I29: 67352 | J29: Drug Item 34 Spray | K29: Katren | L29: KRKA | M29: 1 | N29: 177.33 | O29: 273.62 | P29: 0 | Q29: 0 | S29: 29 | T29: 1 | U29: 1 | V29: 273.62 | W29: 13130000027
A30: 44778 | B30: 0.55001157 | C30: 1028 | D30: 13002561 | E30: 13 | F30: 22589 | G30: Retail Sale | H30: 15 | I30: 30822 | J30: Drug Item 81 Tablets | K30: Protek | L30: Pfizer | M30: 1 | N30: 209.03 | O30: 306.95 | P30: 15.35 | Q30: 15.35 | R30: BONUS_CARD | S30: 29 | T30: 1 | U30: 3 | V30: 291.6 | W30: 13130000028
A31: 44780 | B31: 0.38306713 | C31: 1029 | D31: 13002561 | E31: 13 | F31: 22589 | G31: Retail Sale | H31: 15 | I31: 99791 | J31: Drug Item 87 Gel | K31: Grand Capital | L31: Sanofi | M31: 2 | N31: 481.35 | O31: 616.25 | P31: 30.81 | Q31: 30.81 | R31: BONUS_CARD | S31: 29 | T31: 1 | U31: 3 | V31: 585.44 | W31: 13130000029
A32: 44797 | B32: 0.80503472 | C32: 1030 | D32: 13002561 | E32: 13 | F32: 22589 | G32: Retail Sale | H32: 15 | I32: 45085 | J32: Drug Item 71 Drops | K32: Pharmcomplect | L32: Novartis | M32: 2 | N32: 202.75 | O32: 314.71 | P32: 0 | Q32: 0 | S32: 29 | T32: 1 | U32: 5 | V32: 314.71 | W32: 13130000030
A33: 44804 | B33: 0.84984954 | C33: 1031 | D33: 13002561 | E33: 13 | F33: 22589 | G33: Retail Sale | H33: 18 | I33: 64341 | J33: Drug Item 11 Syrup | K33: Grand Capital | L33: Takeda | M33: 1 | N33: 541.58 | O33: 694.38 | P33: 34.72 | Q33: 34.72 | R33: BONUS_CARD | S33: 29 | T33: 1 | U33: 3 | V33: 659.66 | W33: 13130000031
A34: 44792 | B34: 0.82591435 | C34: 1032 | D34: 13002561 | E34: 13 | F34: 22589 | G34: Retail Sale | H34: 15 | I34: 67951 | J34: Drug Item 90 Tablets | K34: Pulse | L34: Bayer | M34: 3 | N34: 372.78 | O34: 563.36 | P34: 0 | Q34: 0 | S34: 29 | T34: 1 | U34: 6 | V34: 563.36 | W34: 13130000032
A35: 44780 | B35: 0.9005787 | C35: 1033 | D35: 13002561 | E35: 13 | F35: 22589 | G35: Retail Sale | H35: 18 | I35: 38944 | J35: Drug Item 11 Syrup | K35: Avesta | L35: TEVA | M35: 2 | N35: 306.39 | O35: 452.69 | P35: 22.63 | Q35: 22.63 | R35: BONUS_CARD | S35: 29 | T35: 1 | U35: 5 | V35: 430.06 | W35: 13130000033
A36: 44799 | B36: 0.49253472 | C36: 1034 | D36: 13002561 | E36: 13 | F36: 22589 | G36: Retail Sale | H36: 15 | I36: 26854 | J36: Drug Item 60 Gel | K36: Grand Capital | L36: Takeda | M36: 3 | N36: 408.08 | O36: 670.44 | P36: 67.04 | Q36: 67.04 | R36: BONUS_CARD | S36: 29 | T36: 1 | U36: 3 | V36: 603.4 | W36: 13130000034
A37: 44789 | B37: 0.39381944 | C37: 1035 | D37: 13002561 | E37: 13 | F37: 22589 | G37: Retail Sale | H37: 15 | I37: 26775 | J37: Drug Item 18 Tablets | K37: Avesta | L37: Sanofi | M37: 2 | N37: 52.98 | O37: 72.46 | P37: 3.62 | Q37: 3.62 | R37: BONUS_CARD | S37: 29 | T37: 1 | U37: 2 | V37: 68.84 | W37: 13130000035
A38: 44785 | B38: 0.58221065 | C38: 1036 | D38: 13002561 | E38: 13 | F38: 22589 | G38: Retail Sale | H38: 18 | I38: 42575 | J38: Drug Item 5 Ointment | K38: Pulse | L38: Pfizer | M38: 1 | N38: 145.46 | O38: 186.11 | P38: 18.61 | Q38: 18.61 | R38: BONUS_CARD | S38: 29 | T38: 1 | U38: 4 | V38: 167.5 | W38: 13130000036
A39: 44787 | B39: 0.78710648 | C39: 1037 | D39: 13002561 | E39: 13 | F39: 22589 | G39: Retail Sale | H39: 18 | I39: 38901 | J39: Drug Item 88 Spray | K39: Protek | L39: Novartis | M39: 3 | N39: 293.27 | O39: 404.37 | P39: 40.44 | Q39: 40.44 | R39: BONUS_CARD | S39: 29 | T39: 1 | U39: 2 | V39: 363.93 | W39: 13130000037
A40: 44782 | B40: 0.64002315 | C40: 1038 | D40: 13002561 | E40: 13 | F40: 22589 | G40: Retail Sale | H40: 15 | I40: 40966 | J40: Drug Item 54 Tablets | K40: Pharmcomplect | L40: TEVA | M40: 2 | N40: 206.36 | O40: 289.99 | P40: 14.5 | Q40: 14.5 | R40: BONUS_CARD | S40: 29 | T40: 1 | U40: 2 | V40: 275.49 | W40: 13130000038
...

Sheet Pivot_table
A1: Row Labels | B1: Sum of DR_Qty | C1: Sum of Amount | D1: average sales
A2: Drug Item 1 Capsules | B2: 91 | C2: 14826.48 | D2: =B2/30 -> 3.0333333
A3: Drug Item 10 Capsules | B3: 86 | C3: 18652 | D3: =B3/30 -> 2.8666667
A4: Drug Item 11 Syrup | B4: 98 | C4: 20659.18 | D4: =B4/30 -> 3.2666667
A5: Drug Item 12 Injection | B5: 74 | C5: 17389.25 | D5: =B5/30 -> 2.4666667
A6: Drug Item 13 Cream | B6: 73 | C6: 15270.32 | D6: =B6/30 -> 2.4333333
A7: Drug Item 14 Ointment | B7: 92 | C7: 20776.27 | D7: =B7/30 -> 3.0666667
A8: Drug Item 15 Gel | B8: 80 | C8: 16526.52 | D8: =B8/30 -> 2.6666667
A9: Drug Item 16 Spray | B9: 95 | C9: 20246.99 | D9: =B9/30 -> 3.1666667
A10: Drug Item 17 Drops | B10: 126 | C10: 28943.97 | D10: =B10/30 -> 4.2
A11: Drug Item 18 Tablets | B11: 99 | C11: 19132.98 | D11: =B11/30 -> 3.3
A12: Drug Item 19 Capsules | B12: 83 | C12: 19045.54 | D12: =B12/30 -> 2.7666667
A13: Drug Item 2 Syrup | B13: 75 | C13: 14915.62 | D13: =B13/30 -> 2.5
... A91: Drug Item 90 Tablets | B91: 111 | C91: 24092.66 | D91: =B91/30 -> 3.7
A92: Grand Total | B92: 8441 | C92: 1758763

Sheet ABC
F2: ABC Quantity | I2: ABC Amount | L2: ABC Average sales
A3: Row Labels | B3: Quantity | C3: Sum of Amount | D3: Average sales | F3: % | G3: Sum | H3: ABC | I3: % | J3: Sum | K3: ABC | L3: % | M3: Sum | N3: ABC
A4: Drug Item 71 Drops | B4: 130 | C4: 24515.81 | D4: 4.3333333 | F4: 0.015401019 | G4: 0.015401019 | H4: A | I4: 0.016896512 | J4: 0.016896512 | K4: A | L4: =D4/SUM($D$4:$D$93) -> 0.015401019 | M4: =L4 -> 0.015401019 | N4: =IF(M4<0.8,"A",IF(M4< 0.95,"B","C")) -> A | O4: =VLOOKUP(A4,XYZ!A:AK,37,0) -> Z | P4: =H4&K4&N4&O4 -> AAAZ | Q4: A | R4: most important items: generate ~80% of revenue
A5: Drug Item 44 Drops | B5: 127 | C5: 29716.96 | D5: 4.2333333 | F5: 0.015045611 | G5: 0.03044663 | H5: A | I5: 0.016457004 | J5: 0.033353516 | K5: A | L5: =D5/SUM($D$4:$D$93) -> 0.015045611 | M5: =M4+L5 -> 0.03044663 | N5: =IF(M5<0.8,"A",IF(M5< 0.95,"B","C")) -> A | O5: =VLOOKUP(A5,XYZ!A:AK,37,0) -> Z | P5: =H5&K5&N5&O5 -> AAAZ | Q5: B | R5: items to monitor: potential A-category candidates.
A6: Drug Item 17 Drops | B6: 126 | C6: 28943.97 | D6: 4.2 | F6: 0.014927141 | G6: 0.045373771 | H6: A | I6: 0.014389017 | J6: 0.047742532 | K6: A | L6: =D6/SUM($D$4:$D$93) -> 0.014927141 | M6: =M5+L6 -> 0.045373771 | N6: =IF(M6<0.8,"A",IF(M6< 0.95,"B","C")) -> A | O6: =VLOOKUP(A6,XYZ!A:AK,37,0) -> Y | P6: =H6&K6&N6&O6 -> AAAY | Q6: C | R6: low-impact items: insignificant revenue
A7: Drug Item 38 Syrup | B7: 126 | C7: 22879.35 | D7: 4.2 | F7: 0.014927141 | G7: 0.060300912 | H7: A | I7: 0.014352883 | J7: 0.062095416 | K7: A | L7: =D7/SUM($D$4:$D$93) -> 0.014927141 | M7: =M6+L7 -> 0.060300912 | N7: =IF(M7<0.8,"A",IF(M7< 0.95,"B","C")) -> A | O7: =VLOOKUP(A7,XYZ!A:AK,37,0) -> Z | P7: =H7&K7&N7&O7 -> AAAZ
A8: Drug Item 6 Gel | B8: 120 | C8: 23490.75 | D8: 4 | F8: 0.014216325 | G8: 0.074517237 | H8: A | I8: 0.014237734 | J8: 0.07633315 | K8: A | L8: =D8/SUM($D$4:$D$93) -> 0.014216325 | M8: =M7+L8 -> 0.074517237 | N8: =IF(M8<0.8,"A",IF(M8< 0.95,"B","C")) -> A | O8: =VLOOKUP(A8,XYZ!A:AK,37,0) -> Y | P8: =H8&K8&N8&O8 -> AAAY | Q8: X | R8: stable demand items. Must always be available.
A9: Drug Item 82 Capsules | B9: 116 | C9: 25306.87 | D9: 3.8666667 | F9: 0.013742448 | G9: 0.088259685 | H9: A | I9: 0.014004383 | J9: 0.090337532 | K9: A | L9: =D9/SUM($D$4:$D$93) -> 0.013742448 | M9: =M8+L9 -> 0.088259685 | N9: =IF(M9<0.8,"A",IF(M9< 0.95,"B","C")) -> A | O9: =VLOOKUP(A9,XYZ!A:AK,37,0) -> Y | P9: =H9&K9&N9&O9 -> AAAY | Q9: Y | R9: medium or seasonal demand. No need for large stock.
A10: Drug Item 80 Drops | B10: 116 | C10: 23165.39 | D10: 3.8666667 | F10: 0.013742448 | G10: 0.10200213 | H10: A | I10: 0.013939234 | J10: 0.10427677 | K10: A | L10: =D10/SUM($D$4:$D$93) -> 0.013742448 | M10: =M9+L10 -> 0.10200213 | N10: =IF(M10<0.8,"A",IF(M10< 0.95,"B","C")) -> A | O10: =VLOOKUP(A10,XYZ!A:AK,37,0) -> Z | P10: =H10&K10&N10&O10 -> AAAZ | Q10: Z | R10: rare demand items
A11: Drug Item 54 Tablets | B11: 114 | C11: 22358.98 | D11: 3.8 | F11: 0.013505509 | G11: 0.11550764 | H11: A | I11: 0.013698639 | J11: 0.11797541 | K11: A | L11: =D11/SUM($D$4:$D$93) -> 0.013505509 | M11: =M10+L11 -> 0.11550764 | N11: =IF(M11<0.8,"A",IF(M11< 0.95,"B","C")) -> A | O11: =VLOOKUP(A11,XYZ!A:AK,37,0) -> Y | P11: =H11&K11&N11&O11 -> AAAY
A12: Drug Item 45 Tablets | B12: 114 | C12: 20870.33 | D12: 3.8 | F12: 0.013505509 | G12: 0.12901315 | H12: A | I12: 0.01359729 | J12: 0.1315727 | K12: A | L12: =D12/SUM($D$4:$D$93) -> 0.013505509 | M12: =M11+L12 -> 0.12901315 | N12: =IF(M12<0.8,"A",IF(M12< 0.95,"B","C")) -> A | O12: =VLOOKUP(A12,XYZ!A:AK,37,0) -> Y | P12: =H12&K12&N12&O12 -> AAAY
A13: Drug Item 3 Injection | B13: 112 | C13: 23589.23 | D13: 3.7333333 | F13: 0.01326857 | G13: 0.14228172 | H13: A | I13: 0.013412398 | J13: 0.14498509 | K13: A | L13: =D13/SUM($D$4:$D$93) -> 0.01326857 | M13: =M12+L13 -> 0.14228172 | N13: =IF(M13<0.8,"A",IF(M13< 0.95,"B","C")) -> A | O13: =VLOOKUP(A13,XYZ!A:AK,37,0) -> Y | P13: =H13&K13&N13&O13 -> AAAY
A14: Drug Item 90 Tablets | B14: 111 | C14: 24092.66 | D14: 3.7 | F14: 0.013150101 | G14: 0.15543182 | H14: A | I14: 0.013358093 | J14: 0.15834319 | K14: A | L14: =D14/SUM($D$4:$D$93) -> 0.013150101 | M14: =M13+L14 -> 0.15543182 | N14: =IF(M14<0.8,"A",IF(M14< 0.95,"B","C")) -> A | O14: =VLOOKUP(A14,XYZ!A:AK,37,0) -> Y | P14: =H14&K14&N14&O14 -> AAAY
A15: Drug Item 49 Cream | B15: 110 | C15: 22232.57 | D15: 3.6666667 | F15: 0.013031631 | G15: 0.16846345 | H15: A | I15: 0.013356404 | J15: 0.17169959 | K15: A | L15: =D15/SUM($D$4:$D$93) -> 0.013031631 | M15: =M14+L15 -> 0.16846345 | N15: =IF(M15<0.8,"A",IF(M15< 0.95,"B","C")) -> A | O15: =VLOOKUP(A15,XYZ!A:AK,37,0) -> Y | P15: =H15&K15&N15&O15 -> AAAY
A16: Drug Item 22 Cream | B16: 108 | C16: 20288.82 | D16: 3.6 | F16: 0.012794693 | G16: 0.18125814 | H16: A | I16: 0.013253025 | J16: 0.18495262 | K16: A | L16: =D16/SUM($D$4:$D$93) -> 0.012794693 | M16: =M15+L16 -> 0.18125814 | N16: =IF(M16<0.8,"A",IF(M16< 0.95,"B","C")) -> A | O16: =VLOOKUP(A16,XYZ!A:AK,37,0) -> Y | P16: =H16&K16&N16&O16 -> AAAY
A17: Drug Item 5 Ointment | B17: 107 | C17: 22917.25 | D17: 3.5666667 | F17: 0.012676223 | G17: 0.19393437 | H17: A | I17: 0.013171411 | J17: 0.19812403 | K17: A | L17: =D17/SUM($D$4:$D$93) -> 0.012676223 | M17: =M16+L17 -> 0.19393437 | N17: =IF(M17<0.8,"A",IF(M17< 0.95,"B","C")) -> A | O17: =VLOOKUP(A17,XYZ!A:AK,37,0) -> Y | P17: =H17&K17&N17&O17 -> AAAY
A18: Drug Item 60 Gel | B18: 107 | C18: 22429.64 | D18: 3.5666667 | F18: 0.012676223 | G18: 0.20661059 | H18: A | I18: 0.013030323 | J18: 0.21115435 | K18: A | L18: =D18/SUM($D$4:$D$93) -> 0.012676223 | M18: =M17+L18 -> 0.20661059 | N18: =IF(M18<0.8,"A",IF(M18< 0.95,"B","C")) -> A | O18: =VLOOKUP(A18,XYZ!A:AK,37,0) -> Z | P18: =H18&K18&N18&O18 -> AAAZ
A19: Drug Item 33 Gel | B19: 107 | C19: 19049.4 | D19: 3.5666667 | F19: 0.012676223 | G19: 0.21928681 | H19: A | I19: 0.013008774 | J19: 0.22416312 | K19: A | L19: =D19/SUM($D$4:$D$93) -> 0.012676223 | M19: =M18+L19 -> 0.21928681 | N19: =IF(M19<0.8,"A",IF(M19< 0.95,"B","C")) -> A | O19: =VLOOKUP(A19,XYZ!A:AK,37,0) -> Y | P19: =H19&K19&N19&O19 -> AAAY
A20: Drug Item 26 Drops | B20: 107 | C20: 18987.91 | D20: 3.5666667 | F20: 0.012676223 | G20: 0.23196304 | H20: A | I20: 0.012900322 | J20: 0.23706345 | K20: A | L20: =D20/SUM($D$4:$D$93) -> 0.012676223 | M20: =M19+L20 -> 0.23196304 | N20: =IF(M20<0.8,"A",IF(M20< 0.95,"B","C")) -> A | O20: =VLOOKUP(A20,XYZ!A:AK,37,0) -> Z | P20: =H20&K20&N20&O20 -> AAAZ
A21: Drug Item 89 Drops | B21: 106 | C21: 25243.32 | D21: 3.5333333 | F21: 0.012557754 | G21: 0.24452079 | H21: A | I21: 0.012813534 | J21: 0.24987698 | K21: A | L21: =D21/SUM($D$4:$D$93) -> 0.012557754 | M21: =M20+L21 -> 0.24452079 | N21: =IF(M21<0.8,"A",IF(M21< 0.95,"B","C")) -> A | O21: =VLOOKUP(A21,XYZ!A:AK,37,0) -> Y | P21: =H21&K21&N21&O21 -> AAAY
A22: Drug Item 72 Tablets | B22: 106 | C22: 25040.8 | D22: 3.5333333 | F22: 0.012557754 | G22: 0.25707855 | H22: A | I22: 0.012753077 | J22: 0.26263006 | K22: A | L22: =D22/SUM($D$4:$D$93) -> 0.012557754 | M22: =M21+L22 -> 0.25707855 | N22: =IF(M22<0.8,"A",IF(M22< 0.95,"B","C")) -> A | O22: =VLOOKUP(A22,XYZ!A:AK,37,0) -> Y | P22: =H22&K22&N22&O22 -> AAAY
... A93: Drug Item 51 Gel | B93: 56 | C93: 10849.66 | D93: 1.8666667 | F93: 0.006634285 | G93: 1 | H93: C | I93: 0.0061689153 | J93: 1 | K93: C | L93: =D93/SUM($D$4:$D$93) -> 0.006634285 | M93: =M92+L93 -> 1 | N93: =IF(M93<0.8,"A",IF(M93< 0.95,"B","C")) -> C | O93: =VLOOKUP(A93,XYZ!A:AK,37,0) -> Z | P93: =H93&K93&N93&O93 -> CCCZ

Sheet XYZ
C2: Sales Quantity
A3: Sum of DR_Qty | B3: Column Labels
A4: Row Labels | B4: 44774 | C4: 44775 | D4: 44776 | E4: 44777 | F4: 44778 | G4: 44779 | H4: 44780 | I4: 44781 | J4: 44782 | K4: 44783 | L4: 44784 | M4: 44785 | N4: 44786 | O4: 44787 | P4: 44788 | Q4: 44789 | R4: 44790 | S4: 44791 | T4: 44792 | U4: 44793 | V4: 44794 | W4: 44795 | X4: 44796 | Y4: 44797 | Z4: 44798 | AA4: 44799 | AB4: 44800 | AC4: 44801 | AD4: 44802 | AE4: 44803 | AF4: 44804 | AG4: Grand Total | AI4: Days, >20
A5: Drug Item 1 Capsules | B5: 1 | C5: 3 | D5: 6 | E5: 3 | F5: 3 | G5: 11 | I5: 2 | J5: 1 | N5: 1 | O5: 8 | P5: 3 | Q5: 1 | R5: 3 | S5: 11 | T5: 3 | V5: 2 | W5: 3 | X5: 4 | Y5: 2 | Z5: 3 | AA5: 6 | AC5: 3 | AD5: 3 | AF5: 5 | AG5: 91 | AI5: =IF(COUNT(B5:AF5)>=20,COUNT(B5:AF5),"") -> 24 | AJ5: =IF(AVERAGE(B5:AF5)>0,_xlfn.STDEV.P(B5:AF5)/AVERAGE(B5:AF5),"") -> 0.7221879 | AK5: =IF(AJ5<>"",IF(AJ5<=0.3,"X",IF(AJ5<=0.6,"Y","Z")),"") -> Z
A6: Drug Item 10 Capsules | B6: 6 | C6: 2 | D6: 6 | E6: 3 | F6: 3 | H6: 2 | I6: 3 | K6: 6 | L6: 7 | N6: 6 | O6: 5 | P6: 4 | Q6: 2 | R6: 1 | S6: 1 | T6: 2 | W6: 2 | Y6: 5 | AA6: 2 | AC6: 4 | AD6: 10 | AE6: 4 | AG6: 86 | AI6: =IF(COUNT(B6:AF6)>=20,COUNT(B6:AF6),"") -> 22 | AJ6: =IF(AVERAGE(B6:AF6)>0,_xlfn.STDEV.P(B6:AF6)/AVERAGE(B6:AF6),"") -> 0.56631608 | AK6: =IF(AJ6<>"",IF(AJ6<=0.3,"X",IF(AJ6<=0.6,"Y","Z")),"") -> Y
A7: Drug Item 11 Syrup | B7: 2 | D7: 6 | E7: 5 | G7: 7 | H7: 9 | J7: 2 | L7: 2 | M7: 1 | P7: 6 | Q7: 3 | R7: 4 | S7: 2 | T7: 10 | U7: 1 | V7: 6 | W7: 3 | X7: 5 | Z7: 1 | AA7: 4 | AB7: 1 | AC7: 2 | AD7: 2 | AE7: 10 | AF7: 4 | AG7: 98 | AI7: =IF(COUNT(B7:AF7)>=20,COUNT(B7:AF7),"") -> 24 | AJ7: =IF(AVERAGE(B7:AF7)>0,_xlfn.STDEV.P(B7:AF7)/AVERAGE(B7:AF7),"") -> 0.67408753 | AK7: =IF(AJ7<>"",IF(AJ7<=0.3,"X",IF(AJ7<=0.6,"Y","Z")),"") -> Z
A8: Drug Item 12 Injection | B8: 1 | C8: 1 | E8: 3 | F8: 11 | G8: 3 | I8: 6 | M8: 5 | N8: 3 | O8: 2 | P8: 2 | Q8: 3 | T8: 2 | V8: 2 | W8: 4 | X8: 3 | Y8: 8 | Z8: 4 | AB8: 4 | AC8: 3 | AD8: 3 | AF8: 1 | AG8: 74 | AI8: =IF(COUNT(B8:AF8)>=20,COUNT(B8:AF8),"") -> 21 | AJ8: =IF(AVERAGE(B8:AF8)>0,_xlfn.STDEV.P(B8:AF8)/AVERAGE(B8:AF8),"") -> 0.66477697 | AK8: =IF(AJ8<>"",IF(AJ8<=0.3,"X",IF(AJ8<=0.6,"Y","Z")),"") -> Z
A9: Drug Item 13 Cream | B9: 1 | D9: 7 | E9: 3 | F9: 1 | G9: 3 | H9: 2 | I9: 2 | J9: 5 | L9: 3 | M9: 3 | N9: 3 | O9: 3 | P9: 7 | Q9: 2 | T9: 9 | V9: 2 | W9: 3 | X9: 2 | Y9: 2 | Z9: 1 | AB9: 3 | AC9: 2 | AF9: 4 | AG9: 73 | AI9: =IF(COUNT(B9:AF9)>=20,COUNT(B9:AF9),"") -> 23 | AJ9: =IF(AVERAGE(B9:AF9)>0,_xlfn.STDEV.P(B9:AF9)/AVERAGE(B9:AF9),"") -> 0.6277501 | AK9: =IF(AJ9<>"",IF(AJ9<=0.3,"X",IF(AJ9<=0.6,"Y","Z")),"") -> Z
A10: Drug Item 14 Ointment | B10: 2 | C10: 2 | D10: 4 | E10: 6 | F10: 2 | G10: 6 | H10: 3 | J10: 1 | K10: 8 | L10: 7 | M10: 2 | N10: 4 | O10: 3 | P10: 3 | Q10: 1 | T10: 1 | U10: 5 | W10: 1 | X10: 3 | Y10: 5 | Z10: 4 | AA10: 7 | AB10: 1 | AE10: 9 | AF10: 2 | AG10: 92 | AI10: =IF(COUNT(B10:AF10)>=20,COUNT(B10:AF10),"") -> 25 | AJ10: =IF(AVERAGE(B10:AF10)>0,_xlfn.STDEV.P(B10:AF10)/AVERAGE(B10:AF10),"") -> 0.63249289 | AK10: =IF(AJ10<>"",IF(AJ10<=0.3,"X",IF(AJ10<=0.6,"Y","Z")),"") -> Z
A11: Drug Item 15 Gel | B11: 8 | C11: 5 | D11: 2 | G11: 3 | I11: 3 | J11: 4 | K11: 8 | L11: 3 | N11: 2 | O11: 1 | P11: 4 | R11: 3 | S11: 4 | T11: 1 | U11: 3 | V11: 2 | W11: 1 | X11: 5 | Y11: 3 | Z11: 1 | AA11: 1 | AC11: 5 | AE11: 1 | AF11: 7 | AG11: 80 | AI11: =IF(COUNT(B11:AF11)>=20,COUNT(B11:AF11),"") -> 24 | AJ11: =IF(AVERAGE(B11:AF11)>0,_xlfn.STDEV.P(B11:AF11)/AVERAGE(B11:AF11),"") -> 0.62849025 | AK11: =IF(AJ11<>"",IF(AJ11<=0.3,"X",IF(AJ11<=0.6,"Y","Z")),"") -> Z
A12: Drug Item 16 Spray | B12: 1 | C12: 3 | D12: 1 | E12: 7 | F12: 4 | G12: 6 | H12: 1 | I12: 1 | J12: 8 | L12: 4 | M12: 5 | N12: 3 | O12: 2 | P12: 9 | Q12: 3 | R12: 2 | S12: 1 | T12: 2 | V12: 2 | W12: 3 | X12: 2 | Y12: 5 | Z12: 4 | AA12: 7 | AC12: 1 | AD12: 4 | AE12: 1 | AF12: 3 | AG12: 95 | AI12: =IF(COUNT(B12:AF12)>=20,COUNT(B12:AF12),"") -> 28 | AJ12: =IF(AVERAGE(B12:AF12)>0,_xlfn.STDEV.P(B12:AF12)/AVERAGE(B12:AF12),"") -> 0.66532645 | AK12: =IF(AJ12<>"",IF(AJ12<=0.3,"X",IF(AJ12<=0.6,"Y","Z")),"") -> Z
A13: Drug Item 17 Drops | C13: 5 | D13: 12 | E13: 7 | F13: 4 | G13: 8 | H13: 2 | J13: 3 | K13: 5 | L13: 2 | M13: 1 | O13: 4 | P13: 3 | Q13: 5 | S13: 7 | T13: 9 | U13: 3 | V13: 9 | W13: 2 | Y13: 2 | Z13: 5 | AA13: 8 | AB13: 7 | AC13: 3 | AD13: 10 | AG13: 126 | AI13: =IF(COUNT(B13:AF13)>=20,COUNT(B13:AF13),"") -> 24 | AJ13: =IF(AVERAGE(B13:AF13)>0,_xlfn.STDEV.P(B13:AF13)/AVERAGE(B13:AF13),"") -> 0.55600889 | AK13: =IF(AJ13<>"",IF(AJ13<=0.3,"X",IF(AJ13<=0.6,"Y","Z")),"") -> Y
A14: Drug Item 18 Tablets | B14: 5 | C14: 3 | E14: 3 | F14: 5 | H14: 1 | I14: 3 | K14: 2 | L14: 9 | M14: 9 | N14: 4 | P14: 3 | Q14: 2 | R14: 4 | S14: 6 | T14: 2 | U14: 3 | V14: 9 | X14: 4 | Z14: 2 | AC14: 5 | AD14: 2 | AE14: 3 | AF14: 10 | AG14: 99 | AI14: =IF(COUNT(B14:AF14)>=20,COUNT(B14:AF14),"") -> 23 | AJ14: =IF(AVERAGE(B14:AF14)>0,_xlfn.STDEV.P(B14:AF14)/AVERAGE(B14:AF14),"") -> 0.59501723 | AK14: =IF(AJ14<>"",IF(AJ14<=0.3,"X",IF(AJ14<=0.6,"Y","Z")),"") -> Y
A15: Drug Item 19 Capsules | C15: 2 | E15: 3 | F15: 2 | H15: 5 | I15: 2 | J15: 2 | K15: 2 | L15: 3 | M15: 4 | N15: 6 | O15: 5 | P15: 9 | R15: 1 | S15: 2 | T15: 1 | U15: 5 | V15: 4 | W15: 4 | X15: 3 | Z15: 2 | AA15: 1 | AB15: 1 | AC15: 5 | AD15: 1 | AE15: 5 | AF15: 3 | AG15: 83 | AI15: =IF(COUNT(B15:AF15)>=20,COUNT(B15:AF15),"") -> 26 | AJ15: =IF(AVERAGE(B15:AF15)>0,_xlfn.STDEV.P(B15:AF15)/AVERAGE(B15:AF15),"") -> 0.59574628 | AK15: =IF(AJ15<>"",IF(AJ15<=0.3,"X",IF(AJ15<=0.6,"Y","Z")),"") -> Y
A16: Drug Item 2 Syrup | B16: 3 | D16: 4 | E16: 3 | F16: 1 | G16: 3 | H16: 1 | I16: 2 | K16: 9 | O16: 3 | P16: 3 | R16: 3 | V16: 2 | W16: 6 | X16: 3 | Y16: 4 | Z16: 6 | AA16: 3 | AB16: 6 | AD16: 6 | AE16: 3 | AF16: 1 | AG16: 75 | AI16: =IF(COUNT(B16:AF16)>=20,COUNT(B16:AF16),"") -> 21 | AJ16: =IF(AVERAGE(B16:AF16)>0,_xlfn.STDEV.P(B16:AF16)/AVERAGE(B16:AF16),"") -> 0.5503938 | AK16: =IF(AJ16<>"",IF(AJ16<=0.3,"X",IF(AJ16<=0.6,"Y","Z")),"") -> Y
A17: Drug Item 20 Syrup | B17: 2 | C17: 4 | E17: 2 | F17: 6 | G17: 6 | H17: 1 | I17: 8 | J17: 5 | K17: 3 | L17: 5 | M17: 3 | N17: 5 | O17: 3 | Q17: 3 | R17: 3 | T17: 5 | U17: 4 | V17: 8 | W17: 1 | X17: 5 | AA17: 7 | AB17: 3 | AC17: 1 | AD17: 3 | AE17: 2 | AF17: 5 | AG17: 103 | AI17: =IF(COUNT(B17:AF17)>=20,COUNT(B17:AF17),"") -> 26 | AJ17: =IF(AVERAGE(B17:AF17)>0,_xlfn.STDEV.P(B17:AF17)/AVERAGE(B17:AF17),"") -> 0.49742479 | AK17: =IF(AJ17<>"",IF(AJ17<=0.3,"X",IF(AJ17<=0.6,"Y","Z")),"") -> Y
A18: Drug Item 21 Injection | B18: 1 | C18: 2 | E18: 3 | F18: 1 | G18: 1 | I18: 6 | J18: 8 | K18: 5 | L18: 5 | M18: 6 | N18: 2 | O18: 2 | P18: 2 | Q18: 3 | R18: 9 | T18: 4 | U18: 6 | V18: 4 | W18: 11 | X18: 6 | AC18: 3 | AD18: 2 | AF18: 5 | AG18: 97 | AI18: =IF(COUNT(B18:AF18)>=20,COUNT(B18:AF18),"") -> 23 | AJ18: =IF(AVERAGE(B18:AF18)>0,_xlfn.STDEV.P(B18:AF18)/AVERAGE(B18:AF18),"") -> 0.62129976 | AK18: =IF(AJ18<>"",IF(AJ18<=0.3,"X",IF(AJ18<=0.6,"Y","Z")),"") -> Z
A19: Drug Item 22 Cream | B19: 7 | C19: 5 | E19: 7 | F19: 3 | G19: 3 | H19: 3 | I19: 3 | J19: 4 | L19: 2 | M19: 1 | N19: 8 | O19: 3 | P19: 5 | Q19: 6 | R19: 2 | T19: 1 | U19: 3 | V19: 7 | W19: 4 | X19: 6 | Y19: 4 | Z19: 6 | AC19: 1 | AE19: 10 | AF19: 4 | AG19: 108 | AI19: =IF(COUNT(B19:AF19)>=20,COUNT(B19:AF19),"") -> 25 | AJ19: =IF(AVERAGE(B19:AF19)>0,_xlfn.STDEV.P(B19:AF19)/AVERAGE(B19:AF19),"") -> 0.53077447 | AK19: =IF(AJ19<>"",IF(AJ19<=0.3,"X",IF(AJ19<=0.6,"Y","Z")),"") -> Y
A20: Drug Item 23 Ointment | B20: 1 | C20: 6 | E20: 3 | G20: 6 | H20: 3 | I20: 2 | L20: 4 | M20: 11 | N20: 5 | O20: 8 | P20: 3 | Q20: 4 | S20: 3 | T20: 6 | U20: 3 | W20: 1 | X20: 3 | Z20: 4 | AA20: 1 | AF20: 3 | AG20: 80 | AI20: =IF(COUNT(B20:AF20)>=20,COUNT(B20:AF20),"") -> 20 | AJ20: =IF(AVERAGE(B20:AF20)>0,_xlfn.STDEV.P(B20:AF20)/AVERAGE(B20:AF20),"") -> 0.60207973 | AK20: =IF(AJ20<>"",IF(AJ20<=0.3,"X",IF(AJ20<=0.6,"Y","Z")),"") -> Z
A21: Drug Item 24 Gel | B21: 4 | C21: 4 | D21: 10 | F21: 1 | G21: 9 | I21: 2 | J21: 2 | K21: 1 | L21: 2 | M21: 1 | N21: 7 | P21: 1 | Q21: 3 | S21: 3 | T21: 4 | V21: 2 | W21: 4 | X21: 2 | Z21: 2 | AA21: 3 | AC21: 3 | AF21: 3 | AG21: 73 | AI21: =IF(COUNT(B21:AF21)>=20,COUNT(B21:AF21),"") -> 22 | AJ21: =IF(AVERAGE(B21:AF21)>0,_xlfn.STDEV.P(B21:AF21)/AVERAGE(B21:AF21),"") -> 0.71770887 | AK21: =IF(AJ21<>"",IF(AJ21<=0.3,"X",IF(AJ21<=0.6,"Y","Z")),"") -> Z
A22: Drug Item 25 Spray | B22: 5 | C22: 3 | E22: 5 | F22: 3 | I22: 1 | J22: 3 | K22: 1 | L22: 2 | M22: 7 | N22: 1 | O22: 1 | P22: 3 | Q22: 1 | R22: 2 | S22: 3 | U22: 3 | W22: 12 | X22: 1 | Z22: 1 | AA22: 4 | AB22: 5 | AD22: 2 | AF22: 6 | AG22: 75 | AI22: =IF(COUNT(B22:AF22)>=20,COUNT(B22:AF22),"") -> 23 | AJ22: =IF(AVERAGE(B22:AF22)>0,_xlfn.STDEV.P(B22:AF22)/AVERAGE(B22:AF22),"") -> 0.77905926 | AK22: =IF(AJ22<>"",IF(AJ22<=0.3,"X",IF(AJ22<=0.6,"Y","Z")),"") -> Z
A23: Drug Item 26 Drops | B23: 11 | C23: 6 | D23: 1 | E23: 8 | G23: 9 | H23: 3 | I23: 8 | J23: 5 | K23: 5 | L23: 3 | M23: 2 | N23: 5 | O23: 6 | S23: 2 | T23: 1 | U23: 6 | W23: 4 | X23: 1 | Z23: 8 | AB23: 1 | AC23: 6 | AD23: 5 | AE23: 1 | AG23: 107 | AI23: =IF(COUNT(B23:AF23)>=20,COUNT(B23:AF23),"") -> 23 | AJ23: =IF(AVERAGE(B23:AF23)>0,_xlfn.STDEV.P(B23:AF23)/AVERAGE(B23:AF23),"") -> 0.61327214 | AK23: =IF(AJ23<>"",IF(AJ23<=0.3,"X",IF(AJ23<=0.6,"Y","Z")),"") -> Z
A24: Drug Item 27 Tablets | B24: 1 | C24: 3 | D24: 4 | E24: 2 | F24: 5 | G24: 1 | I24: 6 | K24: 6 | N24: 1 | O24: 2 | P24: 2 | Q24: 3 | S24: 3 | T24: 8 | U24: 6 | W24: 3 | X24: 2 | Y24: 6 | Z24: 3 | AA24: 3 | AB24: 1 | AC24: 9 | AE24: 2 | AG24: 82 | AI24: =IF(COUNT(B24:AF24)>=20,COUNT(B24:AF24),"") -> 23 | AJ24: =IF(AVERAGE(B24:AF24)>0,_xlfn.STDEV.P(B24:AF24)/AVERAGE(B24:AF24),"") -> 0.62896571 | AK24: =IF(AJ24<>"",IF(AJ24<=0.3,"X",IF(AJ24<=0.6,"Y","Z")),"") -> Z
A25: Drug Item 28 Capsules | B25: 2 | C25: 1 | D25: 5 | E25: 4 | F25: 3 | H25: 3 | I25: 2 | K25: 2 | M25: 7 | O25: 1 | P25: 5 | Q25: 1 | R25: 5 | S25: 1 | T25: 2 | U25: 5 | V25: 4 | W25: 8 | X25: 3 | Y25: 2 | Z25: 3 | AB25: 3 | AC25: 2 | AD25: 3 | AE25: 5 | AF25: 2 | AG25: 84 | AI25: =IF(COUNT(B25:AF25)>=20,COUNT(B25:AF25),"") -> 26 | AJ25: =IF(AVERAGE(B25:AF25)>0,_xlfn.STDEV.P(B25:AF25)/AVERAGE(B25:AF25),"") -> 0.55838283 | AK25: =IF(AJ25<>"",IF(AJ25<=0.3,"X",IF(AJ25<=0.6,"Y","Z")),"") -> Y
A26: Drug Item 29 Syrup | B26: 9 | D26: 3 | G26: 1 | I26: 3 | J26: 6 | L26: 1 | N26: 3 | O26: 8 | Q26: 3 | S26: 3 | T26: 5 | U26: 5 | V26: 7 | W26: 10 | X26: 1 | Y26: 3 | Z26: 3 | AC26: 2 | AD26: 6 | AE26: 6 | AF26: 3 | AG26: 91 | AI26: =IF(COUNT(B26:AF26)>=20,COUNT(B26:AF26),"") -> 21 | AJ26: =IF(AVERAGE(B26:AF26)>0,_xlfn.STDEV.P(B26:AF26)/AVERAGE(B26:AF26),"") -> 0.58870748 | AK26: =IF(AJ26<>"",IF(AJ26<=0.3,"X",IF(AJ26<=0.6,"Y","Z")),"") -> Y
A27: Drug Item 3 Injection | C27: 9 | D27: 5 | F27: 9 | G27: 3 | H27: 2 | I27: 4 | J27: 3 | K27: 8 | L27: 3 | M27: 5 | N27: 2 | P27: 5 | Q27: 7 | R27: 1 | S27: 1 | U27: 1 | V27: 3 | W27: 3 | X27: 8 | Z27: 3 | AA27: 7 | AB27: 6 | AC27: 7 | AD27: 2 | AE27: 4 | AF27: 1 | AG27: 112 | AI27: =IF(COUNT(B27:AF27)>=20,COUNT(B27:AF27),"") -> 26 | AJ27: =IF(AVERAGE(B27:AF27)>0,_xlfn.STDEV.P(B27:AF27)/AVERAGE(B27:AF27),"") -> 0.58928571 | AK27: =IF(AJ27<>"",IF(AJ27<=0.3,"X",IF(AJ27<=0.6,"Y","Z")),"") -> Y
A28: Drug Item 30 Injection | B28: 4 | C28: 2 | D28: 3 | E28: 5 | G28: 1 | H28: 6 | J28: 3 | K28: 2 | L28: 3 | N28: 4 | P28: 4 | Q28: 4 | R28: 2 | S28: 1 | T28: 2 | U28: 4 | V28: 1 | Z28: 3 | AA28: 3 | AB28: 3 | AC28: 7 | AD28: 2 | AF28: 3 | AG28: 72 | AI28: =IF(COUNT(B28:AF28)>=20,COUNT(B28:AF28),"") -> 23 | AJ28: =IF(AVERAGE(B28:AF28)>0,_xlfn.STDEV.P(B28:AF28)/AVERAGE(B28:AF28),"") -> 0.47385339 | AK28: =IF(AJ28<>"",IF(AJ28<=0.3,"X",IF(AJ28<=0.6,"Y","Z")),"") -> Y
A29: Drug Item 31 Cream | B29: 2 | D29: 4 | E29: 2 | F29: 4 | G29: 4 | H29: 7 | J29: 4 | K29: 4 | M29: 5 | O29: 1 | Q29: 2 | R29: 2 | S29: 4 | U29: 2 | V29: 2 | W29: 2 | X29: 3 | Y29: 3 | Z29: 4 | AA29: 5 | AB29: 6 | AC29: 2 | AD29: 2 | AE29: 3 | AF29: 2 | AG29: 81 | AI29: =IF(COUNT(B29:AF29)>=20,COUNT(B29:AF29),"") -> 25 | AJ29: =IF(AVERAGE(B29:AF29)>0,_xlfn.STDEV.P(B29:AF29)/AVERAGE(B29:AF29),"") -> 0.44752022 | AK29: =IF(AJ29<>"",IF(AJ29<=0.3,"X",IF(AJ29<=0.6,"Y","Z")),"") -> Y
A30: Drug Item 32 Ointment | B30: 9 | D30: 3 | G30: 6 | I30: 3 | J30: 2 | K30: 4 | L30: 10 | M30: 2 | O30: 4 | P30: 5 | Q30: 7 | R30: 3 | S30: 4 | T30: 2 | U30: 4 | V30: 3 | W30: 3 | X30: 2 | Y30: 5 | Z30: 4 | AA30: 1 | AB30: 3 | AC30: 3 | AD30: 3 | AE30: 3 | AF30: 2 | AG30: 100 | AI30: =IF(COUNT(B30:AF30)>=20,COUNT(B30:AF30),"") -> 26 | AJ30: =IF(AVERAGE(B30:AF30)>0,_xlfn.STDEV.P(B30:AF30)/AVERAGE(B30:AF30),"") -> 0.54295488 | AK30: =IF(AJ30<>"",IF(AJ30<=0.3,"X",IF(AJ30<=0.6,"Y","Z")),"") -> Y
A31: Drug Item 33 Gel | B31: 6 | C31: 4 | D31: 6 | E31: 3 | F31: 5 | G31: 2 | H31: 6 | I31: 6 | J31: 2 | K31: 7 | M31: 5 | O31: 10 | Q31: 2 | R31: 10 | S31: 7 | T31: 3 | U31: 5 | V31: 3 | W31: 7 | Z31: 4 | AA31: 1 | AC31: 2 | AE31: 1 | AG31: 107 | AI31: =IF(COUNT(B31:AF31)>=20,COUNT(B31:AF31),"") -> 23 | AJ31: =IF(AVERAGE(B31:AF31)>0,_xlfn.STDEV.P(B31:AF31)/AVERAGE(B31:AF31),"") -> 0.540119 | AK31: =IF(AJ31<>"",IF(AJ31<=0.3,"X",IF(AJ31<=0.6,"Y","Z")),"") -> Y
A32: Drug Item 34 Spray | C32: 6 | D32: 4 | E32: 4 | F32: 3 | G32: 4 | H32: 6 | I32: 5 | J32: 4 | K32: 3 | M32: 1 | N32: 4 | O32: 3 | P32: 3 | Q32: 2 | T32: 6 | V32: 8 | W32: 1 | X32: 4 | Y32: 4 | Z32: 3 | AA32: 1 | AB32: 2 | AC32: 4 | AE32: 2 | AF32: 2 | AG32: 89 | AI32: =IF(COUNT(B32:AF32)>=20,COUNT(B32:AF32),"") -> 25 | AJ32: =IF(AVERAGE(B32:AF32)>0,_xlfn.STDEV.P(B32:AF32)/AVERAGE(B32:AF32),"") -> 0.47723057 | AK32: =IF(AJ32<>"",IF(AJ32<=0.3,"X",IF(AJ32<=0.6,"Y","Z")),"") -> Y
A33: Drug Item 35 Drops | B33: 1 | C33: 4 | D33: 2 | E33: 2 | F33: 1 | G33: 3 | I33: 2 | J33: 2 | K33: 9 | M33: 9 | N33: 4 | R33: 3 | S33: 1 | T33: 2 | U33: 2 | V33: 1 | W33: 3 | X33: 3 | Y33: 6 | AA33: 3 | AB33: 8 | AC33: 8 | AD33: 2 | AF33: 3 | AG33: 84 | AI33: =IF(COUNT(B33:AF33)>=20,COUNT(B33:AF33),"") -> 24 | AJ33: =IF(AVERAGE(B33:AF33)>0,_xlfn.STDEV.P(B33:AF33)/AVERAGE(B33:AF33),"") -> 0.71428571 | AK33: =IF(AJ33<>"",IF(AJ33<=0.3,"X",IF(AJ33<=0.6,"Y","Z")),"") -> Z
A34: Drug Item 36 Tablets | B34: 1 | D34: 5 | E34: 3 | G34: 8 | H34: 2 | I34: 3 | J34: 10 | N34: 2 | O34: 2 | Q34: 11 | R34: 1 | S34: 2 | T34: 6 | U34: 2 | X34: 3 | Z34: 5 | AA34: 12 | AB34: 3 | AC34: 8 | AD34: 1 | AE34: 2 | AF34: 1 | AG34: 93 | AI34: =IF(COUNT(B34:AF34)>=20,COUNT(B34:AF34),"") -> 22 | AJ34: =IF(AVERAGE(B34:AF34)>0,_xlfn.STDEV.P(B34:AF34)/AVERAGE(B34:AF34),"") -> 0.79722318 | AK34: =IF(AJ34<>"",IF(AJ34<=0.3,"X",IF(AJ34<=0.6,"Y","Z")),"") -> Z
A35: Drug Item 37 Capsules | B35: 2 | C35: 3 | D35: 1 | F35: 1 | G35: 1 | H35: 2 | I35: 1 | J35: 3 | L35: 2 | N35: 2 | O35: 4 | P35: 3 | Q35: 6 | R35: 2 | S35: 2 | T35: 6 | U35: 3 | X35: 1 | Y35: 5 | Z35: 3 | AA35: 4 | AB35: 2 | AC35: 4 | AD35: 1 | AE35: 4 | AF35: 1 | AG35: 69 | AI35: =IF(COUNT(B35:AF35)>=20,COUNT(B35:AF35),"") -> 26 | AJ35: =IF(AVERAGE(B35:AF35)>0,_xlfn.STDEV.P(B35:AF35)/AVERAGE(B35:AF35),"") -> 0.56223666 | AK35: =IF(AJ35<>"",IF(AJ35<=0.3,"X",IF(AJ35<=0.6,"Y","Z")),"") -> Y
A36: Drug Item 38 Syrup | B36: 3 | C36: 2 | E36: 4 | G36: 5 | H36: 5 | I36: 1 | K36: 5 | M36: 6 | O36: 4 | P36: 10 | Q36: 8 | R36: 2 | S36: 13 | T36: 10 | U36: 7 | V36: 2 | W36: 1 | X36: 8 | Y36: 3 | Z36: 5 | AA36: 1 | AB36: 4 | AC36: 4 | AD36: 9 | AE36: 4 | AG36: 126 | AI36: =IF(COUNT(B36:AF36)>=20,COUNT(B36:AF36),"") -> 25 | AJ36: =IF(AVERAGE(B36:AF36)>0,_xlfn.STDEV.P(B36:AF36)/AVERAGE(B36:AF36),"") -> 0.61598755 | AK36: =IF(AJ36<>"",IF(AJ36<=0.3,"X",IF(AJ36<=0.6,"Y","Z")),"") -> Z
A37: Drug Item 39 Injection | B37: 4 | C37: 4 | D37: 5 | E37: 1 | F37: 3 | L37: 6 | O37: 9 | P37: 5 | Q37: 5 | R37: 2 | S37: 11 | T37: 3 | U37: 2 | V37: 1 | W37: 3 | X37: 3 | Y37: 7 | Z37: 3 | AA37: 5 | AC37: 4 | AD37: 3 | AE37: 3 | AF37: 3 | AG37: 95 | AI37: =IF(COUNT(B37:AF37)>=20,COUNT(B37:AF37),"") -> 23 | AJ37: =IF(AVERAGE(B37:AF37)>0,_xlfn.STDEV.P(B37:AF37)/AVERAGE(B37:AF37),"") -> 0.56352669 | AK37: =IF(AJ37<>"",IF(AJ37<=0.3,"X",IF(AJ37<=0.6,"Y","Z")),"") -> Y
A38: Drug Item 4 Cream | B38: 5 | C38: 4 | D38: 8 | F38: 3 | H38: 4 | I38: 3 | J38: 4 | K38: 2 | L38: 1 | M38: 4 | N38: 5 | O38: 5 | P38: 3 | R38: 3 | U38: 6 | W38: 6 | X38: 8 | Y38: 1 | Z38: 11 | AA38: 2 | AB38: 3 | AC38: 4 | AD38: 5 | AE38: 6 | AG38: 106 | AI38: =IF(COUNT(B38:AF38)>=20,COUNT(B38:AF38),"") -> 24 | AJ38: =IF(AVERAGE(B38:AF38)>0,_xlfn.STDEV.P(B38:AF38)/AVERAGE(B38:AF38),"") -> 0.51430238 | AK38: =IF(AJ38<>"",IF(AJ38<=0.3,"X",IF(AJ38<=0.6,"Y","Z")),"") -> Y
A39: Drug Item 40 Cream | B39: 3 | C39: 3 | D39: 9 | E39: 7 | G39: 3 | H39: 4 | I39: 4 | J39: 1 | K39: 3 | M39: 11 | O39: 4 | P39: 2 | Q39: 3 | R39: 1 | T39: 2 | V39: 7 | W39: 2 | X39: 2 | Z39: 3 | AA39: 5 | AC39: 2 | AD39: 3 | AE39: 1 | AF39: 5 | AG39: 90 | AI39: =IF(COUNT(B39:AF39)>=20,COUNT(B39:AF39),"") -> 24 | AJ39: =IF(AVERAGE(B39:AF39)>0,_xlfn.STDEV.P(B39:AF39)/AVERAGE(B39:AF39),"") -> 0.65884298 | AK39: =IF(AJ39<>"",IF(AJ39<=0.3,"X",IF(AJ39<=0.6,"Y","Z")),"") -> Z
A40: Drug Item 41 Ointment | B40: 5 | C40: 2 | D40: 3 | E40: 5 | F40: 3 | G40: 3 | H40: 2 | I40: 2 | J40: 1 | L40: 1 | N40: 5 | O40: 4 | P40: 11 | R40: 4 | S40: 4 | T40: 2 | U40: 1 | V40: 3 | W40: 5 | X40: 1 | Y40: 6 | Z40: 3 | AA40: 7 | AB40: 2 | AC40: 6 | AD40: 4 | AE40: 3 | AF40: 7 | AG40: 105 | AI40: =IF(COUNT(B40:AF40)>=20,COUNT(B40:AF40),"") -> 28 | AJ40: =IF(AVERAGE(B40:AF40)>0,_xlfn.STDEV.P(B40:AF40)/AVERAGE(B40:AF40),"") -> 0.59468546 | AK40: =IF(AJ40<>"",IF(AJ40<=0.3,"X",IF(AJ40<=0.6,"Y","Z")),"") -> Y
A41: Drug Item 42 Gel | B41: 6 | C41: 8 | D41: 8 | G41: 3 | H41: 9 | I41: 1 | K41: 2 | M41: 6 | N41: 4 | O41: 2 | P41: 7 | Q41: 3 | R41: 6 | S41: 3 | U41: 2 | V41: 1 | W41: 5 | X41: 3 | Y41: 4 | AA41: 7 | AB41: 4 | AD41: 1 | AE41: 4 | AG41: 99 | AI41: =IF(COUNT(B41:AF41)>=20,COUNT(B41:AF41),"") -> 23 | AJ41: =IF(AVERAGE(B41:AF41)>0,_xlfn.STDEV.P(B41:AF41)/AVERAGE(B41:AF41),"") -> 0.54992556 | AK41: =IF(AJ41<>"",IF(AJ41<=0.3,"X",IF(AJ41<=0.6,"Y","Z")),"") -> Y
...

Sheet Paretto_diagram
A2: Row Labels | B2: Sum of Amount | C2: cumul_sum
A3: Drug Item 44 Drops | B3: 29716.96 | C3: =B3 -> 29716.96 | D3: =C3/SUM(B3:B92) -> 0.016896512
A4: Drug Item 17 Drops | B4: 28943.97 | C4: =C3+B4 -> 58660.93 | D4: =C4/SUM(B4:B93) -> 0.03392676
A5: Drug Item 82 Capsules | B5: 25306.87 | C5: =C4+B5 -> 83967.8 | D5: =C5/SUM(B5:B94) -> 0.049389858
A6: Drug Item 89 Drops | B6: 25243.32 | C6: =C5+B6 -> 109211.12 | D6: =C6/SUM(B6:B95) -> 0.065208641
A7: Drug Item 72 Tablets | B7: 25040.8 | C7: =C6+B7 -> 134251.92 | D7: =C7/SUM(B7:B96) -> 0.081386903
A8: Drug Item 20 Syrup | B8: 24630.39 | C8: =C7+B8 -> 158882.31 | D8: =C8/SUM(B8:B97) -> 0.097803155
A9: Drug Item 71 Drops | B9: 24515.81 | C9: =C8+B9 -> 183398.12 | D9: =C9/SUM(B9:B98) -> 0.11463237
A10: Drug Item 90 Tablets | B10: 24092.66 | C10: =C9+B10 -> 207490.78 | D10: =C10/SUM(B10:B99) -> 0.13170966
A11: Drug Item 69 Gel | B11: 23914.41 | C11: =C10+B11 -> 231405.19 | D11: =C11/SUM(B11:B100) -> 0.14917123
A12: Drug Item 3 Injection | B12: 23589.23 | C12: =C11+B12 -> 254994.42 | D12: =C12/SUM(B12:B101) -> 0.16695133
A13: Drug Item 39 Injection | B13: 23493.72 | C13: =C12+B13 -> 278488.14 | D13: =C13/SUM(B13:B102) -> 0.18519348
A14: Drug Item 6 Gel | B14: 23490.75 | C14: =C13+B14 -> 301978.89 | D14: =C14/SUM(B14:B103) -> 0.2040019
A15: Drug Item 35 Drops | B15: 23308.93 | C15: =C14+B15 -> 325287.82 | D15: =C15/SUM(B15:B104) -> 0.22329171
... A92: Drug Item 51 Gel | B92: 10849.66 | C92: =C91+B92 -> 1758763 | D92: =C92/SUM(B92:B181) -> 162.10305
